Workbook

Sheet Dashboard
A1: SkillCraft Technology — Sales Performance Dashboard (India)
A3: All figures in Indian Rupees (₹) | Data period: Jan 2024 – Dec 2025
A5: Total Sales | D5: Total Profit | G5: Total Orders | J5: Overall Profit Margin
A6: =SUM(Data!L2:L501) -> 41050373 | D6: =SUM(Data!M2:M501) -> 2064674 | G6: =COUNTA(Data!A2:A501) -> 500 | J6: =D6/A6 -> 0.050296108
A9: Category, Region & Trend Analysis
A45: Sub-Category Performance — High / Low Performers (Conditional Formatting)
A47: Sub-Category | B47: Category | C47: Total Sales (INR) | D47: Total Profit (INR) | E47: Profit Margin %
A48: =PivotTables!A49 -> Accessories | B48: =PivotTables!B49 -> Technology | C48: =PivotTables!C49 -> 5679821.2 | D48: =PivotTables!D49 -> 443193.84 | E48: =PivotTables!E49 -> 0.078029541
A49: =PivotTables!A50 -> Art | B49: =PivotTables!B50 -> Office Supplies | C49: =PivotTables!C50 -> 209425.21 | D49: =PivotTables!D50 -> 7153.05 | E49: =PivotTables!E50 -> 0.03415563
A50: =PivotTables!A51 -> Binders | B50: =PivotTables!B51 -> Office Supplies | C50: =PivotTables!C51 -> 201026.93 | D50: =PivotTables!D51 -> 21658.73 | E50: =PivotTables!E51 -> 0.10774044
A51: =PivotTables!A52 -> Bookcases | B51: =PivotTables!B52 -> Furniture | C51: =PivotTables!C52 -> 3529016.7 | D51: =PivotTables!D52 -> 47129.72 | E51: =PivotTables!E52 -> 0.013354916
A52: =PivotTables!A53 -> Chairs | B52: =PivotTables!B53 -> Furniture | C52: =PivotTables!C53 -> 2084952 | D52: =PivotTables!D53 -> 67648.29 | E52: =PivotTables!E53 -> 0.032445969
A53: =PivotTables!A54 -> Copiers | B53: =PivotTables!B54 -> Technology | C53: =PivotTables!C54 -> 8439129.1 | D53: =PivotTables!D54 -> 408188.26 | E53: =PivotTables!E54 -> 0.048368529
A54: =PivotTables!A55 -> Envelopes | B54: =PivotTables!B55 -> Office Supplies | C54: =PivotTables!C55 -> 261262.65 | D54: =PivotTables!D55 -> 9101.56 | E54: =PivotTables!E55 -> 0.03483682
A55: =PivotTables!A56 -> Furnishings | B55: =PivotTables!B56 -> Furniture | C55: =PivotTables!C56 -> 3218362.3 | D55: =PivotTables!D56 -> 161780.2 | E55: =PivotTables!E56 -> 0.050267865
A56: =PivotTables!A57 -> Labels | B56: =PivotTables!B57 -> Office Supplies | C56: =PivotTables!C57 -> 210188.8 | D56: =PivotTables!D57 -> -6761.4 | E56: =PivotTables!E57 -> -0.032168222
A57: =PivotTables!A58 -> Machines | B57: =PivotTables!B58 -> Technology | C57: =PivotTables!C58 -> 7179647.2 | D57: =PivotTables!D58 -> 573765.49 | E57: =PivotTables!E58 -> 0.079915555
A58: =PivotTables!A59 -> Paper | B58: =PivotTables!B59 -> Office Supplies | C58: =PivotTables!C59 -> 151846.16 | D58: =PivotTables!D59 -> 6069.81 | E58: =PivotTables!E59 -> 0.039973418
A59: =PivotTables!A60 -> Phones | B59: =PivotTables!B60 -> Technology | C59: =PivotTables!C60 -> 7501072.4 | D59: =PivotTables!D60 -> 192854.79 | E59: =PivotTables!E60 -> 0.025710296
... A61: =PivotTables!A62 -> Tables | B61: =PivotTables!B62 -> Furniture | C61: =PivotTables!C62 -> 2205539.1 | D61: =PivotTables!D62 -> 125606.58 | E61: =PivotTables!E62 -> 0.05695051

Sheet Data
A1: Order ID | B1: Order Date | C1: Ship Date | D1: Ship Mode | E1: Segment | F1: Region | G1: City | H1: Category | I1: Sub-Category | J1: Quantity | K1: Discount | L1: Sales (INR) | M1: Profit (INR)
A2: IN-2025-1001 | B2: 45946 | C2: 45947 | D2: Standard Class | E2: Consumer | F2: South | G2: Chennai | H2: Furniture | I2: Bookcases | J2: 11 | K2: 0 | L2: 209388.94 | M2: -48603.71
A3: IN-2024-1002 | B3: 45515 | C3: 45517 | D3: Same Day | E3: Consumer | F3: South | G3: Kochi | H3: Technology | I3: Phones | J3: 10 | K3: 0.1 | L3: 413012.08 | M3: 69750.98
A4: IN-2025-1003 | B4: 45640 | C4: 45643 | D4: Same Day | E4: Consumer | F4: West | G4: Mumbai | H4: Furniture | I4: Tables | J4: 2 | K4: 0 | L4: 20513.05 | M4: 3853.15
A5: IN-2024-1004 | B5: 45841 | C5: 45842 | D5: Second Class | E5: Home Office | F5: West | G5: Ahmedabad | H5: Office Supplies | I5: Binders | J5: 12 | K5: 0 | L5: 24211.96 | M5: 6372.36
A6: IN-2025-1005 | B6: 45395 | C6: 45399 | D6: First Class | E6: Corporate | F6: West | G6: Pune | H6: Office Supplies | I6: Art | J6: 4 | K6: 0 | L6: 8541.12 | M6: 986.32
A7: IN-2024-1006 | B7: 45467 | C7: 45472 | D7: First Class | E7: Corporate | F7: South | G7: Kochi | H7: Technology | I7: Machines | J7: 11 | K7: 0 | L7: 225175.94 | M7: -25348.32
A8: IN-2025-1007 | B8: 45324 | C8: 45331 | D8: First Class | E8: Consumer | F8: West | G8: Mumbai | H8: Office Supplies | I8: Art | J8: 4 | K8: 0.5 | L8: 2494.67 | M8: -409.82
A9: IN-2024-1008 | B9: 45434 | C9: 45436 | D9: Second Class | E9: Corporate | F9: East | G9: Guwahati | H9: Technology | I9: Accessories | J9: 3 | K9: 0 | L9: 12768.92 | M9: -2021.26
A10: IN-2025-1009 | B10: 45455 | C10: 45462 | D10: Same Day | E10: Corporate | F10: North | G10: Jaipur | H10: Technology | I10: Copiers | J10: 9 | K10: 0 | L10: 509689.85 | M10: 81054.05
A11: IN-2024-1010 | B11: 45841 | C11: 45848 | D11: Same Day | E11: Corporate | F11: West | G11: Mumbai | H11: Office Supplies | I11: Envelopes | J11: 3 | K11: 0.2 | L11: 6878.56 | M11: 2291.47
A12: IN-2025-1011 | B12: 45474 | C12: 45479 | D12: Second Class | E12: Corporate | F12: South | G12: Chennai | H12: Furniture | I12: Bookcases | J12: 9 | K12: 0.3 | L12: 150762.11 | M12: 6507.41
A13: IN-2024-1012 | B13: 45406 | C13: 45409 | D13: Standard Class | E13: Home Office | F13: North | G13: Chandigarh | H13: Office Supplies | I13: Paper | J13: 2 | K13: 0.1 | L13: 4439.64 | M13: -767.9
... A501: IN-2024-1500 | B501: 45406 | C501: 45407 | D501: Standard Class | E501: Consumer | F501: East | G501: Kolkata | H501: Furniture | I501: Furnishings | J501: 1 | K501: 0 | L501: 20240.27 | M501: 5973.26

Sheet PivotTables
A1: Sales & Profit by Category
A2: Category | B2: Total Sales (INR) | C2: Total Profit (INR) | D2: Profit Margin %
A3: Furniture | B3: =SUMIFS(Data!L2:L501,Data!H2:H501,A3) -> 11037870 | C3: =SUMIFS(Data!M2:M501,Data!H2:H501,A3) -> 402164.79 | D3: =C3/B3 -> 0.036434999
A4: Office Supplies | B4: =SUMIFS(Data!L2:L501,Data!H2:H501,A4) -> 1212832.7 | C4: =SUMIFS(Data!M2:M501,Data!H2:H501,A4) -> 44506.83 | D4: =C4/B4 -> 0.036696594
A5: Technology | B5: =SUMIFS(Data!L2:L501,Data!H2:H501,A5) -> 28799670 | C5: =SUMIFS(Data!M2:M501,Data!H2:H501,A5) -> 1618002.4 | D5: =C5/B5 -> 0.056181282
A6: Total | B6: =SUM(B3:B5) -> 41050373 | C6: =SUM(C3:C5) -> 2064674 | D6: =C6/B6 -> 0.050296108
A9: Sales & Profit by Region
A10: Region | B10: Total Sales (INR) | C10: Total Profit (INR) | D10: Profit Margin %
A11: East | B11: =SUMIFS(Data!L2:L501,Data!F2:F501,A11) -> 7225031.1 | C11: =SUMIFS(Data!M2:M501,Data!F2:F501,A11) -> 234291.63 | D11: =C11/B11 -> 0.032427768
A12: North | B12: =SUMIFS(Data!L2:L501,Data!F2:F501,A12) -> 12518699 | C12: =SUMIFS(Data!M2:M501,Data!F2:F501,A12) -> 817016.15 | D12: =C12/B12 -> 0.065263664
A13: South | B13: =SUMIFS(Data!L2:L501,Data!F2:F501,A13) -> 10876618 | C13: =SUMIFS(Data!M2:M501,Data!F2:F501,A13) -> 331089.29 | D13: =C13/B13 -> 0.030440462
A14: West | B14: =SUMIFS(Data!L2:L501,Data!F2:F501,A14) -> 10430025 | C14: =SUMIFS(Data!M2:M501,Data!F2:F501,A14) -> 682276.93 | D14: =C14/B14 -> 0.0654147
A18: Monthly Sales & Profit Trend
A19: Month | B19: Total Sales (INR) | C19: Total Profit (INR) | D19: Orders
A20: 2024-01 | B20: =SUMPRODUCT((TEXT(Data!B2:B501,"yyyy-mm")=A20)*Data!L2:L501) -> 1634826.8 | C20: =SUMPRODUCT((TEXT(Data!B2:B501,"yyyy-mm")=A20)*Data!M2:M501) -> 16740.89 | D20: =SUMPRODUCT((TEXT(Data!B2:B501,"yyyy-mm")=A20)*1) -> 16
A21: 2024-02 | B21: =SUMPRODUCT((TEXT(Data!B2:B501,"yyyy-mm")=A21)*Data!L2:L501) -> 1056014 | C21: =SUMPRODUCT((TEXT(Data!B2:B501,"yyyy-mm")=A21)*Data!M2:M501) -> 77707.37 | D21: =SUMPRODUCT((TEXT(Data!B2:B501,"yyyy-mm")=A21)*1) -> 24
A22: 2024-03 | B22: =SUMPRODUCT((TEXT(Data!B2:B501,"yyyy-mm")=A22)*Data!L2:L501) -> 1020067.5 | C22: =SUMPRODUCT((TEXT(Data!B2:B501,"yyyy-mm")=A22)*Data!M2:M501) -> 77697.02 | D22: =SUMPRODUCT((TEXT(Data!B2:B501,"yyyy-mm")=A22)*1) -> 21
A23: 2024-04 | B23: =SUMPRODUCT((TEXT(Data!B2:B501,"yyyy-mm")=A23)*Data!L2:L501) -> 3130269 | C23: =SUMPRODUCT((TEXT(Data!B2:B501,"yyyy-mm")=A23)*Data!M2:M501) -> 379787.03 | D23: =SUMPRODUCT((TEXT(Data!B2:B501,"yyyy-mm")=A23)*1) -> 28
A24: 2024-05 | B24: =SUMPRODUCT((TEXT(Data!B2:B501,"yyyy-mm")=A24)*Data!L2:L501) -> 1664587.6 | C24: =SUMPRODUCT((TEXT(Data!B2:B501,"yyyy-mm")=A24)*Data!M2:M501) -> 79380.15 | D24: =SUMPRODUCT((TEXT(Data!B2:B501,"yyyy-mm")=A24)*1) -> 21
A25: 2024-06 | B25: =SUMPRODUCT((TEXT(Data!B2:B501,"yyyy-mm")=A25)*Data!L2:L501) -> 2453249 | C25: =SUMPRODUCT((TEXT(Data!B2:B501,"yyyy-mm")=A25)*Data!M2:M501) -> 84493.29 | D25: =SUMPRODUCT((TEXT(Data!B2:B501,"yyyy-mm")=A25)*1) -> 20
A26: 2024-07 | B26: =SUMPRODUCT((TEXT(Data!B2:B501,"yyyy-mm")=A26)*Data!L2:L501) -> 1604069.9 | C26: =SUMPRODUCT((TEXT(Data!B2:B501,"yyyy-mm")=A26)*Data!M2:M501) -> 98187.97 | D26: =SUMPRODUCT((TEXT(Data!B2:B501,"yyyy-mm")=A26)*1) -> 21
A27: 2024-08 | B27: =SUMPRODUCT((TEXT(Data!B2:B501,"yyyy-mm")=A27)*Data!L2:L501) -> 3027023.4 | C27: =SUMPRODUCT((TEXT(Data!B2:B501,"yyyy-mm")=A27)*Data!M2:M501) -> 216901.2 | D27: =SUMPRODUCT((TEXT(Data!B2:B501,"yyyy-mm")=A27)*1) -> 26
A28: 2024-09 | B28: =SUMPRODUCT((TEXT(Data!B2:B501,"yyyy-mm")=A28)*Data!L2:L501) -> 1621408.4 | C28: =SUMPRODUCT((TEXT(Data!B2:B501,"yyyy-mm")=A28)*Data!M2:M501) -> 141843.4 | D28: =SUMPRODUCT((TEXT(Data!B2:B501,"yyyy-mm")=A28)*1) -> 19
A29: 2024-10 | B29: =SUMPRODUCT((TEXT(Data!B2:B501,"yyyy-mm")=A29)*Data!L2:L501) -> 1686280.7 | C29: =SUMPRODUCT((TEXT(Data!B2:B501,"yyyy-mm")=A29)*Data!M2:M501) -> 362.7 | D29: =SUMPRODUCT((TEXT(Data!B2:B501,"yyyy-mm")=A29)*1) -> 18
A30: 2024-11 | B30: =SUMPRODUCT((TEXT(Data!B2:B501,"yyyy-mm")=A30)*Data!L2:L501) -> 1765557 | C30: =SUMPRODUCT((TEXT(Data!B2:B501,"yyyy-mm")=A30)*Data!M2:M501) -> 135633.31 | D30: =SUMPRODUCT((TEXT(Data!B2:B501,"yyyy-mm")=A30)*1) -> 19
A31: 2024-12 | B31: =SUMPRODUCT((TEXT(Data!B2:B501,"yyyy-mm")=A31)*Data!L2:L501) -> 1857364.1 | C31: =SUMPRODUCT((TEXT(Data!B2:B501,"yyyy-mm")=A31)*Data!M2:M501) -> 76677.81 | D31: =SUMPRODUCT((TEXT(Data!B2:B501,"yyyy-mm")=A31)*1) -> 21
A32: 2025-01 | B32: =SUMPRODUCT((TEXT(Data!B2:B501,"yyyy-mm")=A32)*Data!L2:L501) -> 1123703.2 | C32: =SUMPRODUCT((TEXT(Data!B2:B501,"yyyy-mm")=A32)*Data!M2:M501) -> 104982.39 | D32: =SUMPRODUCT((TEXT(Data!B2:B501,"yyyy-mm")=A32)*1) -> 16
A33: 2025-02 | B33: =SUMPRODUCT((TEXT(Data!B2:B501,"yyyy-mm")=A33)*Data!L2:L501) -> 1722624.5 | C33: =SUMPRODUCT((TEXT(Data!B2:B501,"yyyy-mm")=A33)*Data!M2:M501) -> -112558.63 | D33: =SUMPRODUCT((TEXT(Data!B2:B501,"yyyy-mm")=A33)*1) -> 20
A34: 2025-03 | B34: =SUMPRODUCT((TEXT(Data!B2:B501,"yyyy-mm")=A34)*Data!L2:L501) -> 1136796 | C34: =SUMPRODUCT((TEXT(Data!B2:B501,"yyyy-mm")=A34)*Data!M2:M501) -> 155129.65 | D34: =SUMPRODUCT((TEXT(Data!B2:B501,"yyyy-mm")=A34)*1) -> 16
A35: 2025-04 | B35: =SUMPRODUCT((TEXT(Data!B2:B501,"yyyy-mm")=A35)*Data!L2:L501) -> 1239539.9 | C35: =SUMPRODUCT((TEXT(Data!B2:B501,"yyyy-mm")=A35)*Data!M2:M501) -> 123803.03 | D35: =SUMPRODUCT((TEXT(Data!B2:B501,"yyyy-mm")=A35)*1) -> 22
A36: 2025-05 | B36: =SUMPRODUCT((TEXT(Data!B2:B501,"yyyy-mm")=A36)*Data!L2:L501) -> 1259128.6 | C36: =SUMPRODUCT((TEXT(Data!B2:B501,"yyyy-mm")=A36)*Data!M2:M501) -> 64344.44 | D36: =SUMPRODUCT((TEXT(Data!B2:B501,"yyyy-mm")=A36)*1) -> 17
A37: 2025-06 | B37: =SUMPRODUCT((TEXT(Data!B2:B501,"yyyy-mm")=A37)*Data!L2:L501) -> 1880619.3 | C37: =SUMPRODUCT((TEXT(Data!B2:B501,"yyyy-mm")=A37)*Data!M2:M501) -> 140824.57 | D37: =SUMPRODUCT((TEXT(Data!B2:B501,"yyyy-mm")=A37)*1) -> 20
A38: 2025-07 | B38: =SUMPRODUCT((TEXT(Data!B2:B501,"yyyy-mm")=A38)*Data!L2:L501) -> 1768225.6 | C38: =SUMPRODUCT((TEXT(Data!B2:B501,"yyyy-mm")=A38)*Data!M2:M501) -> -113090.2 | D38: =SUMPRODUCT((TEXT(Data!B2:B501,"yyyy-mm")=A38)*1) -> 22
A39: 2025-08 | B39: =SUMPRODUCT((TEXT(Data!B2:B501,"yyyy-mm")=A39)*Data!L2:L501) -> 1100622 | C39: =SUMPRODUCT((TEXT(Data!B2:B501,"yyyy-mm")=A39)*Data!M2:M501) -> 160766.8 | D39: =SUMPRODUCT((TEXT(Data!B2:B501,"yyyy-mm")=A39)*1) -> 18
A40: 2025-09 | B40: =SUMPRODUCT((TEXT(Data!B2:B501,"yyyy-mm")=A40)*Data!L2:L501) -> 3209041.3 | C40: =SUMPRODUCT((TEXT(Data!B2:B501,"yyyy-mm")=A40)*Data!M2:M501) -> -23923.25 | D40: =SUMPRODUCT((TEXT(Data!B2:B501,"yyyy-mm")=A40)*1) -> 22
A41: 2025-10 | B41: =SUMPRODUCT((TEXT(Data!B2:B501,"yyyy-mm")=A41)*Data!L2:L501) -> 1839086.3 | C41: =SUMPRODUCT((TEXT(Data!B2:B501,"yyyy-mm")=A41)*Data!M2:M501) -> 87583.23 | D41: =SUMPRODUCT((TEXT(Data!B2:B501,"yyyy-mm")=A41)*1) -> 32
A42: 2025-11 | B42: =SUMPRODUCT((TEXT(Data!B2:B501,"yyyy-mm")=A42)*Data!L2:L501) -> 1499383.1 | C42: =SUMPRODUCT((TEXT(Data!B2:B501,"yyyy-mm")=A42)*Data!M2:M501) -> 97293.6 | D42: =SUMPRODUCT((TEXT(Data!B2:B501,"yyyy-mm")=A42)*1) -> 22
A43: 2025-12 | B43: =SUMPRODUCT((TEXT(Data!B2:B501,"yyyy-mm")=A43)*Data!L2:L501) -> 750885.52 | C43: =SUMPRODUCT((TEXT(Data!B2:B501,"yyyy-mm")=A43)*Data!M2:M501) -> -5893.77 | D43: =SUMPRODUCT((TEXT(Data!B2:B501,"yyyy-mm")=A43)*1) -> 19
A47: Sub-Category Performance (High / Low Performers)
A48: Sub-Category | B48: Category | C48: Total Sales (INR) | D48: Total Profit (INR) | E48: Profit Margin %
...
